mplus_output/bi-37-MHAS_W4.out
Mplus VERSION 8.1 (Mac)
MUTHEN & MUTHEN
05/27/2020  10:29 PM

INPUT INSTRUCTIONS

  DATA:
  FILE = "bi-37-MHAS_W4.dat";

  VARIABLE:
  NAMES = mplusid UDAY UMON UYER UWR1 UWR2 UWR3 UANI UNUM2 UFCO3 UFRE2 UWD UVSC;
   MISSING=.;
   CATEGORICAL ARE all; idvariable = mplusid;
  ANALYSIS:
  estimator = wlsmv; coverage=0;
  MODEL:
  g by UDAY * ;
   g by UMON * ;
   g by UYER * ;
   g by UANI * ;
   g by UWR1 * ;
   g by UWR2 * ;
   g by UWR3 * ;
   g by UWD * ;
   g by UVSC * ;
   g by UNUM2 * ;
   g by UFCO3 * ;
   g by UFRE2 * ;
   s1 by UWR1 * ;
   s1 by UWR2 * ;
   s1 by UWR3 * ;
   s1 by UWD * ;
   g @ 1;
   s1 @ 1 ;
   g with s1 @ 0 ;

  OUTPUT:
  standardized; svalues;



*** WARNING
  Data set contains cases with missing on all variables.
  These cases were not included in the analysis.
  Number of cases with missing on all variables:  81
   1 WARNING(S) FOUND IN THE INPUT INSTRUCTIONS




SUMMARY OF ANALYSIS

Number of groups                                                 1
Number of observations                                       13459

Number of dependent variables                                   12
Number of independent variables                                  0
Number of continuous latent variables                            2

Observed dependent variables

  Binary and ordered categorical (ordinal)
   UDAY        UMON        UYER        UWR1        UWR2        UWR3
   UANI        UNUM2       UFCO3       UFRE2       UWD         UVSC

Continuous latent variables
   G           S1

Variables with special functions

  ID variable           MPLUSID

Estimator                                                    WLSMV
Maximum number of iterations                                  1000
Convergence criterion                                    0.500D-04
Maximum number of steepest descent iterations                   20
Maximum number of iterations for H1                           2000
Convergence criterion for H1                             0.100D-03
Parameterization                                             DELTA
Link                                                        PROBIT

Input data file(s)
  bi-37-MHAS_W4.dat

Input data format  FREE


SUMMARY OF DATA

     Number of missing data patterns            46


COVARIANCE COVERAGE OF DATA

Minimum covariance coverage value   0.000


     PROPORTION OF DATA PRESENT


           Covariance Coverage
              UDAY          UMON          UYER          UWR1          UWR2
              ________      ________      ________      ________      ________
 UDAY           1.000
 UMON           1.000         1.000
 UYER           1.000         1.000         1.000
 UWR1           0.997         0.997         0.997         0.997
 UWR2           0.997         0.997         0.997         0.997         0.997
 UWR3           0.997         0.997         0.997         0.997         0.997
 UANI           0.997         0.997         0.997         0.996         0.996
 UNUM2          0.956         0.956         0.956         0.955         0.955
 UFCO3          0.935         0.935         0.935         0.934         0.934
 UFRE2          0.926         0.926         0.926         0.925         0.925
 UWD            0.995         0.995         0.995         0.995         0.995
 UVSC           0.934         0.934         0.934         0.933         0.933


           Covariance Coverage
              UWR3          UANI          UNUM2         UFCO3         UFRE2
              ________      ________      ________      ________      ________
 UWR3           0.997
 UANI           0.996         0.997
 UNUM2          0.955         0.955         0.956
 UFCO3          0.934         0.935         0.907         0.935
 UFRE2          0.925         0.926         0.900         0.925         0.926
 UWD            0.995         0.994         0.954         0.933         0.925
 UVSC           0.933         0.933         0.905         0.931         0.923


           Covariance Coverage
              UWD           UVSC
              ________      ________
 UWD            0.995
 UVSC           0.931         0.934


UNIVARIATE PROPORTIONS AND COUNTS FOR CATEGORICAL VARIABLES

    UDAY
      Category 1    0.277         3733.000
      Category 2    0.723         9726.000
    UMON
      Category 1    0.093         1253.000
      Category 2    0.907        12206.000
    UYER
      Category 1    0.192         2588.000
      Category 2    0.808        10871.000
    UWR1
      Category 1    0.012          156.000
      Category 2    0.037          503.000
      Category 3    0.102         1362.000
      Category 4    0.210         2821.000
      Category 5    0.275         3689.000
      Category 6    0.232         3113.000
      Category 7    0.104         1399.000
      Category 8    0.024          328.000
      Category 9    0.004           47.000
    UWR2
      Category 1    0.007           94.000
      Category 2    0.008          114.000
      Category 3    0.028          377.000
      Category 4    0.102         1374.000
      Category 5    0.219         2942.000
      Category 6    0.280         3756.000
      Category 7    0.230         3084.000
      Category 8    0.101         1361.000
      Category 9    0.024          316.000
    UWR3
      Category 1    0.010          133.000
      Category 2    0.008          113.000
      Category 3    0.020          265.000
      Category 4    0.063          839.000
      Category 5    0.152         2037.000
      Category 6    0.227         3049.000
      Category 7    0.270         3629.000
      Category 8    0.180         2421.000
      Category 9    0.069          931.000
    UANI
      Category 1    0.009          124.000
      Category 2    0.045          608.000
      Category 3    0.116         1561.000
      Category 4    0.200         2683.000
      Category 5    0.224         3008.000
      Category 6    0.130         1746.000
      Category 7    0.140         1881.000
      Category 8    0.083         1111.000
      Category 9    0.036          483.000
      Category 10    0.016          217.000
    UNUM2
      Category 1    0.132         1697.000
      Category 2    0.868        11167.000
    UFCO3
      Category 1    0.008          100.000
      Category 2    0.004           55.000
      Category 3    0.019          236.000
      Category 4    0.023          290.000
      Category 5    0.052          658.000
      Category 6    0.120         1513.000
      Category 7    0.773         9738.000
    UFRE2
      Category 1    0.058          727.000
      Category 2    0.012          147.000
      Category 3    0.042          525.000
      Category 4    0.060          742.000
      Category 5    0.128         1596.000
      Category 6    0.183         2276.000
      Category 7    0.518         6453.000
    UWD
      Category 1    0.094         1263.000
      Category 2    0.045          599.000
      Category 3    0.075         1000.000
      Category 4    0.112         1498.000
      Category 5    0.173         2315.000
      Category 6    0.203         2717.000
      Category 7    0.168         2252.000
      Category 8    0.096         1280.000
      Category 9    0.035          472.000
    UVSC
      Category 1    0.034          429.000
      Category 2    0.068          849.000
      Category 3    0.100         1256.000
      Category 4    0.126         1586.000
      Category 5    0.134         1683.000
      Category 6    0.127         1595.000
      Category 7    0.108         1363.000
      Category 8    0.095         1190.000
      Category 9    0.083         1040.000
      Category 10    0.125         1575.000



THE MODEL ESTIMATION TERMINATED NORMALLY



MODEL FIT INFORMATION

Number of Free Parameters                       82

Chi-Square Test of Model Fit

          Value                           4556.426*
          Degrees of Freedom                    50
          P-Value                           0.0000

*   The chi-square value for MLM, MLMV, MLR, ULSMV, WLSM and WLSMV cannot be used
